
<mujoco model="testPassiveWalker">

    <compiler inertiafromgeom='true' angle='degree'/>
    <option gravity='0 0 -9.81'/>
    <asset>
		<!-- Sets sky rendering
		-->
        <texture type="skybox" builtin="gradient" width="100" height="100" rgb1="1 1 1"
            rgb2="1 1 1"/>
		<!-- Not clear to me where this is used yet
		-->
        <texture name="texgeom" type="cube" builtin="flat" mark="cross" width="127" height="1278"
            rgb1="0.1 0.8 0.1" rgb2="0.8 0.6 0.4" markrgb="1 1 1" random="0.01"/>
		<!-- Sets floor rendering
		-->
        <texture name="texplane" type="2d" builtin="checker" rgb1=".2 .3 .4" rgb2=".1 0.15 0.2"
            width="1000" height="1000"/>
		<!-- Create materials based on textures above
		-->
        <material name='MatPlane' reflectance='0.5' texture="texplane"/>
        <material name='geom' texture="texgeom" texuniform="true"/>
    </asset>

	<default>
    <site type="sphere" rgba=".2 .2 .5 .1" size="5e-3"/>
        <camera pos='1 1 1' euler='90 0 0'/>
	</default>

	<worldbody>
        <light directional='false' diffuse='.8 .8 .8' specular='0.3 0.3 0.3' pos='0 0 40.5' dir='0 0 -1'/>

        <body name='axes' pos='20e-3 -1e-3 0'>
          <geom name='x' type='cylinder' fromto='100e-3 0 0 170e-3 0 0' size='5e-3' rgba='0 0 1 1'/>
          <geom name='y' type='cylinder' fromto='100e-3 0 0 100e-3 70e-3 0' size='5e-3' rgba='0 1 0 1'/>
          <geom name='z' type='cylinder' fromto='100e-3 0 0 100e-3 0 70e-3' size='5e-3' rgba='1 0 0 1'/>
        </body>

        <body name='left_wheel' pos='0 -172.5e-3 0' euler='0 0 0'>
          <geom name='left_spoke' density='5e3' type='cylinder' size='2.5e-3 96.25e-3' pos = '5e-3 -86.25e-3 0' euler='90 0 0'/>
          <joint name='left_wheel' type='hinge' axis='1 0 0'  pos='0 0 0' frictional='true' frictionloss='1e-1' />
          <body name='left_foothold' pos='40e-3 -185e-3 0' euler='0 0 0'>
            <geom name='left_foothold' density='5e3'  type='box' size='80e-3 5e-3 30e-3' pos='0 0 50e-3' euler='0 90 0'/>
            <joint name='left_pedal' type='hinge' axis='1 0 0' pos='0 0 0' frictional='true' frictionloss='1e-1' />
            <site name="left_foothold_bottom" pos='0 0 0'/>
            <site name="left_foothold_top"    pos='0 0 74e-3'/>
          </body>
        </body>

        <body name='right_wheel' pos='0 -172.5e-3 0' euler='0 0 0'>
          <geom name='right_spoke' density='5e3' type='cylinder' size='2.5e-3 96.25e-3' pos = '-5e-3 -86.25e-3 0' euler='90 0 0'/>
          <joint name='right_wheel' type='hinge' axis='1 0 0'  pos='0 0 0' frictional='true' frictionloss='1e-1' />
          <body name='right_foothold' pos='-40e-3 -185e-3 0' euler='0 0 0'>
            <geom name='right_foothold' density='5e3'  type='box' size='80e-3 5e-3 30e-3' pos='0 0 50e-3' euler='0 90 0'/>
            <joint name='right_pedal' type='hinge' axis='1 0 0' pos='0 0 0' frictional='true' frictionloss='1e-1' />
            <site name="right_foothold_bottom" pos='0 0 0'/>
            <site name="right_foothold_top"    pos='0 0 74e-3'/>
          </body>
        </body>

	</worldbody>

<actuator>

  <motor name='right_wheel' gear='1' joint='right_wheel' ctrllimited='true' ctrlrange='-1 1' />
  <motor name='left_wheel' gear='1' joint='left_wheel' ctrllimited='true' ctrlrange='-1 1' />

</actuator>

</mujoco>
