
<mujoco model="testPassiveWalker">

    <asset>
		<!-- Sets sky rendering
		-->
        <texture type="skybox" builtin="gradient" width="100" height="100" rgb1=".5 .8 .5" 
            rgb2="0 0 0"/>  
		<!-- Not clear to me where this is used yet
		-->
        <texture name="texgeom" type="cube" builtin="flat" mark="cross" width="127" height="1278" 
            rgb1="0.1 0.8 0.1" rgb2="0.8 0.6 0.4" markrgb="1 1 1" random="0.01"/>  
		<!-- Sets floor rendering
		-->
        <texture name="texplane" type="2d" builtin="checker" rgb1=".2 .3 .4" rgb2=".1 0.15 0.2" 
            width="100" height="100"/>  
		<!-- Create materials based on textures above
		-->
        <material name='MatPlane' reflectance='0.5' texture="texplane"/>
        <material name='geom' texture="texgeom" texuniform="true"/>
    </asset>
	
	<default>
		<default class = 'thigh'>
			<geom fromto = '0 0 0 0 0 -0.3' type='capsule' size='0.05' />
		</default>
		<default class = 'shin'>
			<geom fromto = '0 0 0 0 0 -0.2' type='capsule' size='0.05' />
		</default>
		<default class = 'foot_cap1'>
			<geom type='capsule' fromto='-.07 -0.02 0 0.14 -0.04 0'  size='0.027' />
		</default>
		<default class = 'foot_cap2'>
			<geom  type='capsule' fromto='-.07 0 0 0.14  0.02 0'  size='0.027' />
		</default>
		<default class = 'hip_joint_x'>
			<joint type='hinge' pos='0 0 0' axis='1 0 0' range='-25 5'   damping='5' stiffness='10' armature='0.01' />
		</default>
		<default class = 'hip_joint_y'>
            <joint type='hinge' pos='0 0 0' axis='0 1 0' range='-110 20' damping='5' stiffness='20' armature='0.0080' />
		</default>
		<default class = 'hip_joint_z'>
            <joint type='hinge' pos='0 0 0' axis='0 0 1' range='-60 35'  damping='5' stiffness='10' armature='0.01' />
		</default>
		<default class = 'knee_joint'>
			<joint type='hinge' pos='0 0 .02' axis='0 -1 0' range='-160 -2' armature='0.0060' />
		</default>
		<default class = 'ankle_joint_x'>
			<joint type='hinge' pos='0 0 0.04' axis='1 0 0.5' range='-50 50' stiffness='1'  armature='0.0006' />
		</default>
		<default class = 'ankle_joint_y'>
            <joint type='hinge' pos='0 0 0.08' axis='0 1 0'   range='-50 50' stiffness='4' armature='0.0008' />
		</default>
	</default>
	
	<worldbody>
        <light directional='false' diffuse='.8 .8 .8' specular='0.3 0.3 0.3' pos='0 0 4.5' dir='0 0 -1'/>
		
		<!-- Everything pretty self explanatory, condim = 3 sets the contact type to Regular frictional contact, opposing slip in the tangent plane. see http://mujoco.org/book/modeling.html#CSchema for details
		-->
        <geom name='floor' pos='0 0 0' size='10 10 0.125' euler='80 0 0' type='plane' material="MatPlane" condim='3'/>
		
        <body name='pelvis' pos='0 0 1.4' >
		    <joint name='root' type='free' pos='0 0 0' limited='false' damping='0' armature='0' stiffness='0'/>
			
			<!-- Details on attributes of geoms here: http://mujoco.org/book/modeling.html
			-->
            <geom name='torso1' type='capsule' fromto='0 -.05 0 0 .05 0'  size='0.05' />
			
			<body name='right_leg' pos='0 0.075 -0.025' >
			<joint name='right_hip_x' class = 'hip_joint_x'/>
			<joint name='right_hip_y' class = 'hip_joint_y'/>
			<joint name='right_hip_z' class = 'hip_joint_z'/>
			<geom class="thigh" name='right_thigh'/>
				<body name='right_shin' pos='0 0 -0.4' >
				<joint name='right_knee' class = 'knee_joint'/>
				<geom name='right_shin' class = 'shin'/>
                    <body name='right_foot' pos='0 0 -0.3' >
						<joint name='right_ankle_x' class = 'ankle_joint_x'/>
						<joint name='right_ankle_y' class = 'ankle_joint_y'/>
                        <geom class = 'foot_cap1' name='right_foot_cap1'/>
                        <geom class = 'foot_cap1' name='right_foot_cap2'/>
					</body>
				</body>
			</body>
			<body name='left_leg' pos='0 -0.075 -0.025' >
			<joint name='left_hip_x' class = 'hip_joint_x'/>
			<joint name='left_hip_y' class = 'hip_joint_y'/>
			<joint name='left_hip_z' class = 'hip_joint_z'/>
			<geom class="thigh" name='left_thigh'/>
				<body name='left_shin' pos='0 0 -0.4' >
				<joint name='left_knee' class = 'knee_joint'/>
				<geom name='left_shin' class = 'shin'/>
                    <body name='left_foot' pos='0 0 -0.3' >
						<joint name='left_ankle_x' class = 'ankle_joint_x'/>
						<joint name='left_ankle_y' class = 'ankle_joint_y'/>
                        <geom class = 'foot_cap1' name='left_foot_cap1'/>
                        <geom class = 'foot_cap2' name='left_foot_cap2'/>
					</body>
				</body>
			</body>
		</body>
		
	</worldbody>
</mujoco>